 * Serving Flask app 'app'
 * Debug mode: on
[31m[1mWARNING: This is a development server. Do not use it in a production deployment. Use a production WSGI server instead.[0m
 * Running on http://127.0.0.1:5010
[33mPress CTRL+C to quit[0m
 * Restarting with stat
 * Debugger is active!
 * Debugger PIN: 197-879-355
127.0.0.1 - - [11/Aug/2025 17:44:13] "[35m[1mGET /invoices HTTP/1.1[0m" 500 -
Traceback (most recent call last):
  File "/Users/keijovalting/Library/Python/3.9/lib/python/site-packages/sqlalchemy/engine/base.py", line 1969, in _exec_single_context
    self.dialect.do_execute(
  File "/Users/keijovalting/Library/Python/3.9/lib/python/site-packages/sqlalchemy/engine/default.py", line 922, in do_execute
    cursor.execute(statement, parameters)
sqlite3.OperationalError: no such table: clients

The above exception was the direct cause of the following exception:

Traceback (most recent call last):
  File "/Users/keijovalting/Library/Python/3.9/lib/python/site-packages/flask/app.py", line 1498, in __call__
    return self.wsgi_app(environ, start_response)
  File "/Users/keijovalting/Library/Python/3.9/lib/python/site-packages/flask/app.py", line 1476, in wsgi_app
    response = self.handle_exception(e)
  File "/Users/keijovalting/Library/Python/3.9/lib/python/site-packages/flask/app.py", line 1473, in wsgi_app
    response = self.full_dispatch_request()
  File "/Users/keijovalting/Library/Python/3.9/lib/python/site-packages/flask/app.py", line 882, in full_dispatch_request
    rv = self.handle_user_exception(e)
  File "/Users/keijovalting/Library/Python/3.9/lib/python/site-packages/flask/app.py", line 880, in full_dispatch_request
    rv = self.dispatch_request()
  File "/Users/keijovalting/Library/Python/3.9/lib/python/site-packages/flask/app.py", line 865, in dispatch_request
    return self.ensure_sync(self.view_functions[rule.endpoint])(**view_args)  # type: ignore[no-any-return]
  File "/Users/keijovalting/Downloads/billipocket_gpt5/app/routes/invoices.py", line 18, in invoices
    clients = Client.query.order_by(Client.name.asc()).all()
  File "/Users/keijovalting/Library/Python/3.9/lib/python/site-packages/sqlalchemy/orm/query.py", line 2693, in all
    return self._iter().all()  # type: ignore
  File "/Users/keijovalting/Library/Python/3.9/lib/python/site-packages/sqlalchemy/orm/query.py", line 2847, in _iter
    result: Union[ScalarResult[_T], Result[_T]] = self.session.execute(
  File "/Users/keijovalting/Library/Python/3.9/lib/python/site-packages/sqlalchemy/orm/session.py", line 2308, in execute
    return self._execute_internal(
  File "/Users/keijovalting/Library/Python/3.9/lib/python/site-packages/sqlalchemy/orm/session.py", line 2190, in _execute_internal
    result: Result[Any] = compile_state_cls.orm_execute_statement(
  File "/Users/keijovalting/Library/Python/3.9/lib/python/site-packages/sqlalchemy/orm/context.py", line 293, in orm_execute_statement
    result = conn.execute(
  File "/Users/keijovalting/Library/Python/3.9/lib/python/site-packages/sqlalchemy/engine/base.py", line 1416, in execute
    return meth(
  File "/Users/keijovalting/Library/Python/3.9/lib/python/site-packages/sqlalchemy/sql/elements.py", line 516, in _execute_on_connection
    return connection._execute_clauseelement(
  File "/Users/keijovalting/Library/Python/3.9/lib/python/site-packages/sqlalchemy/engine/base.py", line 1639, in _execute_clauseelement
    ret = self._execute_context(
  File "/Users/keijovalting/Library/Python/3.9/lib/python/site-packages/sqlalchemy/engine/base.py", line 1848, in _execute_context
    return self._exec_single_context(
  File "/Users/keijovalting/Library/Python/3.9/lib/python/site-packages/sqlalchemy/engine/base.py", line 1988, in _exec_single_context
    self._handle_dbapi_exception(
  File "/Users/keijovalting/Library/Python/3.9/lib/python/site-packages/sqlalchemy/engine/base.py", line 2343, in _handle_dbapi_exception
    raise sqlalchemy_exception.with_traceback(exc_info[2]) from e
  File "/Users/keijovalting/Library/Python/3.9/lib/python/site-packages/sqlalchemy/engine/base.py", line 1969, in _exec_single_context
    self.dialect.do_execute(
  File "/Users/keijovalting/Library/Python/3.9/lib/python/site-packages/sqlalchemy/engine/default.py", line 922, in do_execute
    cursor.execute(statement, parameters)
sqlalchemy.exc.OperationalError: (sqlite3.OperationalError) no such table: clients
[SQL: SELECT clients.id AS clients_id, clients.name AS clients_name, clients.registry_code AS clients_registry_code, clients.email AS clients_email, clients.phone AS clients_phone, clients.address AS clients_address, clients.created_at AS clients_created_at 
FROM clients ORDER BY clients.name ASC]
(Background on this error at: https://sqlalche.me/e/20/e3q8)
127.0.0.1 - - [11/Aug/2025 17:44:13] "GET /invoices?__debugger__=yes&cmd=resource&f=debugger.js HTTP/1.1" 200 -
127.0.0.1 - - [11/Aug/2025 17:44:13] "GET /invoices?__debugger__=yes&cmd=resource&f=style.css HTTP/1.1" 200 -
127.0.0.1 - - [11/Aug/2025 17:44:13] "[36mGET /invoices?__debugger__=yes&cmd=resource&f=console.png HTTP/1.1[0m" 304 -
127.0.0.1 - - [11/Aug/2025 17:50:49] "[35m[1mGET / HTTP/1.1[0m" 500 -
Traceback (most recent call last):
  File "/Users/keijovalting/Library/Python/3.9/lib/python/site-packages/sqlalchemy/engine/base.py", line 1969, in _exec_single_context
    self.dialect.do_execute(
  File "/Users/keijovalting/Library/Python/3.9/lib/python/site-packages/sqlalchemy/engine/default.py", line 922, in do_execute
    cursor.execute(statement, parameters)
sqlite3.OperationalError: no such table: invoices

The above exception was the direct cause of the following exception:

Traceback (most recent call last):
  File "/Users/keijovalting/Library/Python/3.9/lib/python/site-packages/flask/app.py", line 1498, in __call__
    return self.wsgi_app(environ, start_response)
  File "/Users/keijovalting/Library/Python/3.9/lib/python/site-packages/flask/app.py", line 1476, in wsgi_app
    response = self.handle_exception(e)
  File "/Users/keijovalting/Library/Python/3.9/lib/python/site-packages/flask/app.py", line 1473, in wsgi_app
    response = self.full_dispatch_request()
  File "/Users/keijovalting/Library/Python/3.9/lib/python/site-packages/flask/app.py", line 882, in full_dispatch_request
    rv = self.handle_user_exception(e)
  File "/Users/keijovalting/Library/Python/3.9/lib/python/site-packages/flask/app.py", line 880, in full_dispatch_request
    rv = self.dispatch_request()
  File "/Users/keijovalting/Library/Python/3.9/lib/python/site-packages/flask/app.py", line 865, in dispatch_request
    return self.ensure_sync(self.view_functions[rule.endpoint])(**view_args)  # type: ignore[no-any-return]
  File "/Users/keijovalting/Downloads/billipocket_gpt5/app/routes/dashboard.py", line 17, in overview
    updated_count = Invoice.update_overdue_invoices()
  File "/Users/keijovalting/Downloads/billipocket_gpt5/app/models.py", line 206, in update_overdue_invoices
    overdue_invoices = cls.query.filter(
  File "/Users/keijovalting/Library/Python/3.9/lib/python/site-packages/sqlalchemy/orm/query.py", line 2693, in all
    return self._iter().all()  # type: ignore
  File "/Users/keijovalting/Library/Python/3.9/lib/python/site-packages/sqlalchemy/orm/query.py", line 2847, in _iter
    result: Union[ScalarResult[_T], Result[_T]] = self.session.execute(
  File "/Users/keijovalting/Library/Python/3.9/lib/python/site-packages/sqlalchemy/orm/session.py", line 2308, in execute
    return self._execute_internal(
  File "/Users/keijovalting/Library/Python/3.9/lib/python/site-packages/sqlalchemy/orm/session.py", line 2190, in _execute_internal
    result: Result[Any] = compile_state_cls.orm_execute_statement(
  File "/Users/keijovalting/Library/Python/3.9/lib/python/site-packages/sqlalchemy/orm/context.py", line 293, in orm_execute_statement
    result = conn.execute(
  File "/Users/keijovalting/Library/Python/3.9/lib/python/site-packages/sqlalchemy/engine/base.py", line 1416, in execute
    return meth(
  File "/Users/keijovalting/Library/Python/3.9/lib/python/site-packages/sqlalchemy/sql/elements.py", line 516, in _execute_on_connection
    return connection._execute_clauseelement(
  File "/Users/keijovalting/Library/Python/3.9/lib/python/site-packages/sqlalchemy/engine/base.py", line 1639, in _execute_clauseelement
    ret = self._execute_context(
  File "/Users/keijovalting/Library/Python/3.9/lib/python/site-packages/sqlalchemy/engine/base.py", line 1848, in _execute_context
    return self._exec_single_context(
  File "/Users/keijovalting/Library/Python/3.9/lib/python/site-packages/sqlalchemy/engine/base.py", line 1988, in _exec_single_context
    self._handle_dbapi_exception(
  File "/Users/keijovalting/Library/Python/3.9/lib/python/site-packages/sqlalchemy/engine/base.py", line 2343, in _handle_dbapi_exception
    raise sqlalchemy_exception.with_traceback(exc_info[2]) from e
  File "/Users/keijovalting/Library/Python/3.9/lib/python/site-packages/sqlalchemy/engine/base.py", line 1969, in _exec_single_context
    self.dialect.do_execute(
  File "/Users/keijovalting/Library/Python/3.9/lib/python/site-packages/sqlalchemy/engine/default.py", line 922, in do_execute
    cursor.execute(statement, parameters)
sqlalchemy.exc.OperationalError: (sqlite3.OperationalError) no such table: invoices
[SQL: SELECT invoices.id AS invoices_id, invoices.number AS invoices_number, invoices.client_id AS invoices_client_id, invoices.date AS invoices_date, invoices.due_date AS invoices_due_date, invoices.subtotal AS invoices_subtotal, invoices.vat_rate_id AS invoices_vat_rate_id, invoices.vat_rate AS invoices_vat_rate, invoices.total AS invoices_total, invoices.status AS invoices_status, invoices.created_at AS invoices_created_at, invoices.updated_at AS invoices_updated_at 
FROM invoices 
WHERE invoices.due_date < ? AND invoices.status = ?]
[parameters: ('2025-08-11', 'saadetud')]
(Background on this error at: https://sqlalche.me/e/20/e3q8)
127.0.0.1 - - [11/Aug/2025 17:50:49] "[36mGET /?__debugger__=yes&cmd=resource&f=console.png HTTP/1.1[0m" 304 -
127.0.0.1 - - [11/Aug/2025 17:50:49] "[36mGET /?__debugger__=yes&cmd=resource&f=style.css HTTP/1.1[0m" 304 -
127.0.0.1 - - [11/Aug/2025 17:50:49] "[36mGET /?__debugger__=yes&cmd=resource&f=debugger.js HTTP/1.1[0m" 304 -
